Workbook

Sheet Dashboard
B2: DASHBOARD | TIMELINE DE ESTACAS | N2: AUXILIARES — NÃO EDITAR
B3: Avanço físico do estaqueamento, produtividade por equipamento, ensaios PIT e ocorrências de campo. Todos os números vêm da aba "Timeline Estacas". | N3: Semana mínima | O3: =IF($B$7="TODAS",0,VALUE(RIGHT($B$7,2))) -> 0
N4: Semana máxima | O4: =IF($B$7="TODAS",9999,VALUE(RIGHT($B$7,2))) -> 9999
B5: FILTROS DE ANÁLISE | N5: Última semana com produção | O5: =MAX('Dados Dashboard'!$AE$2:$AE$243) -> 43
B6: Semana selecionada | E6: Data inicial | H6: Data final | K6: Data de referência (hoje) | N6: Primeiro dia com produção | O6: =MIN('Dados Dashboard'!$AA$2:$AA$243) -> 46233
B7: TODAS | E7: 46227 | H7: 46387 | K7: =TODAY() -> 46266 | N7: Dias úteis decorridos | O7: =IF($O$6=0,0,NETWORKDAYS($O$6,MAX('Dados Dashboard'!$AA$2:$AA$243))) -> 20
B9: AVANÇO FÍSICO DO ESTAQUEAMENTO • ACUMULADO DO ESCOPO (não depende dos filtros)
B10: Estacas Realizadas | E10: Estacas Programadas (escopo) | H10: Saldo a Executar | K10: % de Avanço Físico
B11: =SUM('Dados Dashboard'!$Q$2:$Q$243) -> 105 | E11: =COUNT('Programação Estaca'!$A$2:$A$1000) -> 224 | H11: =MAX(0,$E$11-$B$11) -> 119 | K11: =IF($E$11=0,0,$B$11/$E$11) -> 0.46875
B12: Dias com Produção | E12: Ritmo Médio (estacas/dia produtivo) | H12: Ritmo Efetivo (estacas/dia útil) | K12: Previsão de Término (ritmo efetivo)
B13: =SUM('Dados Dashboard'!$Z$2:$Z$243) -> 12 | E13: =IF($B$13=0,0,$B$11/$B$13) -> 8.75 | H13: =IF($O$7=0,0,$B$11/$O$7) -> 5.25 | K13: =IF($H$13=0,"",WORKDAY($K$7,ROUNDUP($H$11/$H$13,0))) -> 46297
B14: =REPT("■",ROUND($K$11*40,0))&REPT("·",40-ROUND($K$11*40,0))&" "&TEXT($B$11,"#,##0")&" de "&TEXT($E$11,"#,##0")&" estacas ("&TEXT($K$11,"0.0%")&") | "&TEXT($B$13,"#,##0")&" de "&TEXT($O$7,"#,##0")&" dias úteis com produção ("&TEXT(IF($O$7=0,0,$B$13/$O$7),"0%")&")" -> ■■■■■■■■■■■■■■■■■■■····················· 105 de 224 estacas (46.9%) | 12 de 20 dias úteis com produção (60%)
B16: DESEMPENHO NO RECORTE SELECIONADO • responde aos filtros acima
B17: Estacas Realizadas | E17: Dias com Produção | H17: Média por Dia Produtivo | K17: Dias com Ocorrência
B18: =SUMIFS('Dados Dashboard'!$Q:$Q,'Dados Dashboard'!$D:$D,">="&$O$3,'Dados Dashboard'!$D:$D,"<="&$O$4,'Dados Dashboard'!$A:$A,">="&$E$7,'Dados Dashboard'!$A:$A,"<="&$H$7) -> 105 | E18: =SUMIFS('Dados Dashboard'!$Z:$Z,'Dados Dashboard'!$D:$D,">="&$O$3,'Dados Dashboard'!$D:$D,"<="&$O$4,'Dados Dashboard'!$A:$A,">="&$E$7,'Dados Dashboard'!$A:$A,"<="&$H$7) -> 12 | H18: =IF($E$18=0,0,$B$18/$E$18) -> 8.75 | K18: =SUMIFS('Dados Dashboard'!$R:$R,'Dados Dashboard'!$D:$D,">="&$O$3,'Dados Dashboard'!$D:$D,"<="&$O$4,'Dados Dashboard'!$A:$A,">="&$E$7,'Dados Dashboard'!$A:$A,"<="&$H$7) -> 10
B19: Estacas Equip 1 | E19: Estacas Equip 2 | H19: Ensaios PIT Programados | K19: PIT Vencidos (até hoje)
B20: =SUMIFS('Dados Dashboard'!$S:$S,'Dados Dashboard'!$D:$D,">="&$O$3,'Dados Dashboard'!$D:$D,"<="&$O$4,'Dados Dashboard'!$A:$A,">="&$E$7,'Dados Dashboard'!$A:$A,"<="&$H$7) -> 92 | E20: =SUMIFS('Dados Dashboard'!$T:$T,'Dados Dashboard'!$D:$D,">="&$O$3,'Dados Dashboard'!$D:$D,"<="&$O$4,'Dados Dashboard'!$A:$A,">="&$E$7,'Dados Dashboard'!$A:$A,"<="&$H$7) -> 13 | H20: =SUMIFS('Dados Dashboard'!$U:$U,'Dados Dashboard'!$D:$D,">="&$O$3,'Dados Dashboard'!$D:$D,"<="&$O$4,'Dados Dashboard'!$A:$A,">="&$E$7,'Dados Dashboard'!$A:$A,"<="&$H$7) -> 89 | K20: =SUMIFS('Dados Dashboard'!$V:$V,'Dados Dashboard'!$D:$D,">="&$O$3,'Dados Dashboard'!$D:$D,"<="&$O$4,'Dados Dashboard'!$A:$A,">="&$E$7,'Dados Dashboard'!$A:$A,"<="&$H$7) -> 46
B22: PRODUÇÃO POR FRENTE (RECORTE) | H22: AVANÇO DO ESCOPO
B23: Frente / Atividade | C23: Quantidade | H23: Situação | I23: Estacas
B24: Estacas Equip 1 | C24: =$B$20 -> 92 | H24: Realizadas | I24: =$B$11 -> 105
B25: Estacas Equip 2 | C25: =$E$20 -> 13 | H25: A executar | I25: =$H$11 -> 119
B26: Ensaios PIT | C26: =$H$20 -> 89
B27: PCE | C27: =SUMIFS('Dados Dashboard'!$AB:$AB,'Dados Dashboard'!$D:$D,">="&$O$3,'Dados Dashboard'!$D:$D,"<="&$O$4,'Dados Dashboard'!$A:$A,">="&$E$7,'Dados Dashboard'!$A:$A,"<="&$H$7) -> 0
B28: Escavação | C28: =SUMIFS('Dados Dashboard'!$AC:$AC,'Dados Dashboard'!$D:$D,">="&$O$3,'Dados Dashboard'!$D:$D,"<="&$O$4,'Dados Dashboard'!$A:$A,">="&$E$7,'Dados Dashboard'!$A:$A,"<="&$H$7) -> 0
B29: Bloco | C29: =SUMIFS('Dados Dashboard'!$AD:$AD,'Dados Dashboard'!$D:$D,">="&$O$3,'Dados Dashboard'!$D:$D,"<="&$O$4,'Dados Dashboard'!$A:$A,">="&$E$7,'Dados Dashboard'!$A:$A,"<="&$H$7) -> 0
B48: TENDÊNCIA SEMANAL E CURVA DE AVANÇO
B49: Semana | C49: Estacas realizadas | E49: Acumulado | F49: Ocorrências
B50: =Listas!A3 -> S-39 | C50: =SUMIFS('Dados Dashboard'!$Q:$Q,'Dados Dashboard'!$D:$D,VALUE(RIGHT($B50,2))) -> 3 | E50: =IF(VALUE(RIGHT($B50,2))>$O$5,"",SUM($C$50:C50)) -> 3 | F50: =SUMIFS('Dados Dashboard'!$R:$R,'Dados Dashboard'!$D:$D,VALUE(RIGHT($B50,2))) -> 1
B51: =Listas!A4 -> S-40 | C51: =SUMIFS('Dados Dashboard'!$Q:$Q,'Dados Dashboard'!$D:$D,VALUE(RIGHT($B51,2))) -> 1 | E51: =IF(VALUE(RIGHT($B51,2))>$O$5,"",SUM($C$50:C51)) -> 4 | F51: =SUMIFS('Dados Dashboard'!$R:$R,'Dados Dashboard'!$D:$D,VALUE(RIGHT($B51,2))) -> 4
B52: =Listas!A5 -> S-41 | C52: =SUMIFS('Dados Dashboard'!$Q:$Q,'Dados Dashboard'!$D:$D,VALUE(RIGHT($B52,2))) -> 22 | E52: =IF(VALUE(RIGHT($B52,2))>$O$5,"",SUM($C$50:C52)) -> 26 | F52: =SUMIFS('Dados Dashboard'!$R:$R,'Dados Dashboard'!$D:$D,VALUE(RIGHT($B52,2))) -> 2
B53: =Listas!A6 -> S-42 | C53: =SUMIFS('Dados Dashboard'!$Q:$Q,'Dados Dashboard'!$D:$D,VALUE(RIGHT($B53,2))) -> 28 | E53: =IF(VALUE(RIGHT($B53,2))>$O$5,"",SUM($C$50:C53)) -> 54 | F53: =SUMIFS('Dados Dashboard'!$R:$R,'Dados Dashboard'!$D:$D,VALUE(RIGHT($B53,2))) -> 3
B54: =Listas!A7 -> S-43 | C54: =SUMIFS('Dados Dashboard'!$Q:$Q,'Dados Dashboard'!$D:$D,VALUE(RIGHT($B54,2))) -> 51 | E54: =IF(VALUE(RIGHT($B54,2))>$O$5,"",SUM($C$50:C54)) -> 105 | F54: =SUMIFS('Dados Dashboard'!$R:$R,'Dados Dashboard'!$D:$D,VALUE(RIGHT($B54,2))) -> 0
B55: =Listas!A8 -> S-44 | C55: =SUMIFS('Dados Dashboard'!$Q:$Q,'Dados Dashboard'!$D:$D,VALUE(RIGHT($B55,2))) -> 0 | E55: =IF(VALUE(RIGHT($B55,2))>$O$5,"",SUM($C$50:C55)) | F55: =SUMIFS('Dados Dashboard'!$R:$R,'Dados Dashboard'!$D:$D,VALUE(RIGHT($B55,2))) -> 0
B56: =Listas!A9 -> S-45 | C56: =SUMIFS('Dados Dashboard'!$Q:$Q,'Dados Dashboard'!$D:$D,VALUE(RIGHT($B56,2))) -> 0 | E56: =IF(VALUE(RIGHT($B56,2))>$O$5,"",SUM($C$50:C56)) | F56: =SUMIFS('Dados Dashboard'!$R:$R,'Dados Dashboard'!$D:$D,VALUE(RIGHT($B56,2))) -> 0
B57: =Listas!A10 -> S-46 | C57: =SUMIFS('Dados Dashboard'!$Q:$Q,'Dados Dashboard'!$D:$D,VALUE(RIGHT($B57,2))) -> 0 | E57: =IF(VALUE(RIGHT($B57,2))>$O$5,"",SUM($C$50:C57)) | F57: =SUMIFS('Dados Dashboard'!$R:$R,'Dados Dashboard'!$D:$D,VALUE(RIGHT($B57,2))) -> 0
B58: =Listas!A11 -> S-47 | C58: =SUMIFS('Dados Dashboard'!$Q:$Q,'Dados Dashboard'!$D:$D,VALUE(RIGHT($B58,2))) -> 0 | E58: =IF(VALUE(RIGHT($B58,2))>$O$5,"",SUM($C$50:C58)) | F58: =SUMIFS('Dados Dashboard'!$R:$R,'Dados Dashboard'!$D:$D,VALUE(RIGHT($B58,2))) -> 0
B59: =Listas!A12 -> S-48 | C59: =SUMIFS('Dados Dashboard'!$Q:$Q,'Dados Dashboard'!$D:$D,VALUE(RIGHT($B59,2))) -> 0 | E59: =IF(VALUE(RIGHT($B59,2))>$O$5,"",SUM($C$50:C59)) | F59: =SUMIFS('Dados Dashboard'!$R:$R,'Dados Dashboard'!$D:$D,VALUE(RIGHT($B59,2))) -> 0
B60: =Listas!A13 -> S-49 | C60: =SUMIFS('Dados Dashboard'!$Q:$Q,'Dados Dashboard'!$D:$D,VALUE(RIGHT($B60,2))) -> 0 | E60: =IF(VALUE(RIGHT($B60,2))>$O$5,"",SUM($C$50:C60)) | F60: =SUMIFS('Dados Dashboard'!$R:$R,'Dados Dashboard'!$D:$D,VALUE(RIGHT($B60,2))) -> 0
B61: =Listas!A14 -> S-50 | C61: =SUMIFS('Dados Dashboard'!$Q:$Q,'Dados Dashboard'!$D:$D,VALUE(RIGHT($B61,2))) -> 0 | E61: =IF(VALUE(RIGHT($B61,2))>$O$5,"",SUM($C$50:C61)) | F61: =SUMIFS('Dados Dashboard'!$R:$R,'Dados Dashboard'!$D:$D,VALUE(RIGHT($B61,2))) -> 0
... B72: =Listas!A25 -> S-61 | C72: =SUMIFS('Dados Dashboard'!$Q:$Q,'Dados Dashboard'!$D:$D,VALUE(RIGHT($B72,2))) -> 0 | E72: =IF(VALUE(RIGHT($B72,2))>$O$5,"",SUM($C$50:C72)) | F72: =SUMIFS('Dados Dashboard'!$R:$R,'Dados Dashboard'!$D:$D,VALUE(RIGHT($B72,2))) -> 0
...

Sheet Timeline Estacas
A1: DATA | B1: DIA SEMANA | C1: DIAS A PARTIR A.S. | D1: SEMANA PROGRAMAÇÃO | E1: SEM | F1: Equip 1 | G1: EIXO | H1: Equip 2 | I1: EIXO | J1: PIT | K1: PCE | L1: ESCAVAÇÃO | M1: BLOCO | N1: OBSERVAÇÃO | O1: m³ Concreto
A2: 46227 | B2: =A2 -> 46227 | C2: 266 | D2: 39 | E2: =_xlfn.CONCAT("S-",TEXT(D2,"00")) -> S-39
A3: 46228 | B3: =A3 -> 46228 | C3: 267 | D3: 39 | E3: =_xlfn.CONCAT("S-",TEXT(D3,"00")) -> S-39
A4: 46229 | B4: =A4 -> 46229 | C4: 268 | D4: 39 | E4: =_xlfn.CONCAT("S-",TEXT(D4,"00")) -> S-39
A5: 46230 | B5: =A5 -> 46230 | C5: 269 | D5: 39 | E5: =_xlfn.CONCAT("S-",TEXT(D5,"00")) -> S-39
A6: 46231 | B6: =A6 -> 46231 | C6: 270 | D6: 39 | E6: =_xlfn.CONCAT("S-",TEXT(D6,"00")) -> S-39
A7: 46232 | B7: =A7 -> 46232 | C7: 271 | D7: 39 | E7: =_xlfn.CONCAT("S-",TEXT(D7,"00")) -> S-39 | N7: Teste inicial do equipamento
A8: 46233 | B8: =A8 -> 46233 | C8: 272 | D8: 39 | E8: =_xlfn.CONCAT("S-",TEXT(D8,"00")) -> S-39 | F8: 70 | I8: A | J8: =A8+14 -> 46247
A9: 46233 | B9: 46233 | C9: 272 | D9: 39 | F9: 71 | I9: A | J9: =A9+14 -> 46247
A10: 46233 | B10: 46233 | C10: 272 | D10: 39 | F10: 74 | I10: A | J10: =A10+14 -> 46247
A11: 46234 | B11: =A11 -> 46234 | C11: 273 | D11: =D2+1 -> 40 | E11: =_xlfn.CONCAT("S-",TEXT(D11,"00")) -> S-40 | N11: Bomba entupida
A12: 46235 | B12: =A12 -> 46235 | C12: 274 | D12: =D3+1 -> 40 | E12: =_xlfn.CONCAT("S-",TEXT(D12,"00")) -> S-40
A13: 46236 | B13: =A13 -> 46236 | C13: 275 | D13: =D4+1 -> 40 | E13: =_xlfn.CONCAT("S-",TEXT(D13,"00")) -> S-40
A14: 46237 | B14: =A14 -> 46237 | C14: 276 | D14: =D5+1 -> 40 | E14: =_xlfn.CONCAT("S-",TEXT(D14,"00")) -> S-40 | N14: Manutenção do trado
A15: 46238 | B15: =A15 -> 46238 | C15: 277 | D15: =D6+1 -> 40 | E15: =_xlfn.CONCAT("S-",TEXT(D15,"00")) -> S-40 | F15: 5 | I15: B | J15: =A15+14 -> 46252
A16: 46239 | B16: =A16 -> 46239 | C16: 278 | D16: =D7+1 -> 40 | E16: =_xlfn.CONCAT("S-",TEXT(D16,"00")) -> S-40 | N16: Bomba entupida
A17: 46240 | B17: =A17 -> 46240 | C17: 279 | D17: =D8+1 -> 40 | E17: =_xlfn.CONCAT("S-",TEXT(D17,"00")) -> S-40 | N17: Manutenção do trado
A18: 46241 | B18: =A18 -> 46241 | C18: 280 | D18: =D11+1 -> 41 | E18: =_xlfn.CONCAT("S-",TEXT(D18,"00")) -> S-41 | N18: Desmontagem / Manutenção do trado
A19: 46242 | B19: =A19 -> 46242 | C19: 281 | D19: =D12+1 -> 41 | E19: =_xlfn.CONCAT("S-",TEXT(D19,"00")) -> S-41
A20: 46243 | B20: =A20 -> 46243 | C20: 282 | D20: =D13+1 -> 41 | E20: =_xlfn.CONCAT("S-",TEXT(D20,"00")) -> S-41
A21: 46244 | B21: =A21 -> 46244 | C21: 283 | D21: =D14+1 -> 41 | E21: =_xlfn.CONCAT("S-",TEXT(D21,"00")) -> S-41 | N21: Teste equipamento Rei Hélice - 7min perfuração
A22: 46245 | B22: =A22 -> 46245 | C22: 284 | D22: =D15+1 -> 41 | E22: =_xlfn.CONCAT("S-",TEXT(D22,"00")) -> S-41 | F22: 1 | I22: B | J22: =A22+14 -> 46259
A23: 46245 | B23: =A23 -> 46245 | C23: 284 | D23: =D16+1 -> 41 | F23: 9 | I23: B | J23: =A23+14 -> 46259
A24: 46245 | B24: =A24 -> 46245 | C24: 284 | D24: =D17+1 -> 41 | F24: 13 | I24: B | J24: =A24+14 -> 46259
A25: 46246 | B25: =A25 -> 46246 | C25: 285 | D25: =D16+1 -> 41 | E25: =_xlfn.CONCAT("S-",TEXT(D25,"00")) -> S-41 | F25: 14 | I25: B | J25: =A25+14 -> 46260
A26: 46246 | B26: 46246 | C26: 285 | D26: 41 | F26: 15 | I26: B | J26: =A26+14 -> 46260
A27: 46246 | B27: 46246 | C27: 285 | D27: 41 | F27: 18 | I27: B | J27: =A27+14 -> 46260
A28: 46246 | B28: 46246 | C28: 285 | D28: 41 | F28: 19 | I28: B | J28: =A28+14 -> 46260
A29: 46246 | B29: 46246 | C29: 285 | D29: 41 | F29: 22 | I29: B | J29: =A29+14 -> 46260
A30: 46246 | B30: 46246 | C30: 285 | D30: 41 | F30: 23 | I30: B | J30: =A30+14 -> 46260
A31: 46246 | B31: 46246 | C31: 285 | D31: 41 | F31: 26 | I31: B | J31: =A31+14 -> 46260
A32: 46246 | B32: 46246 | C32: 285 | D32: 41 | F32: 27 | I32: B | J32: =A32+14 -> 46260
A33: 46246 | B33: 46246 | C33: 285 | D33: 41 | F33: 86 | I33: A | J33: =A33+14 -> 46260
A34: 46246 | B34: 46246 | C34: 285 | D34: 41 | F34: 87 | I34: A | J34: =A34+14 -> 46260
A35: 46247 | B35: =A35 -> 46247 | C35: 286 | D35: =D17+1 -> 41 | E35: =_xlfn.CONCAT("S-",TEXT(D35,"00")) -> S-41 | F35: 90 | I35: A | J35: =A35+14 -> 46261
A36: 46247 | B36: 46247 | C36: 286 | D36: 41 | F36: 91 | I36: A | J36: =A36+14 -> 46261
A37: 46247 | B37: 46247 | C37: 286 | D37: 41 | F37: 94 | I37: A | J37: =A37+14 -> 46261
A38: 46247 | B38: 46247 | C38: 286 | D38: 41 | F38: 95 | I38: A | J38: =A38+14 -> 46261
A39: 46247 | B39: 46247 | C39: 286 | D39: 41 | F39: 98 | I39: A | J39: =A39+14 -> 46261
A40: 46247 | B40: 46247 | C40: 286 | D40: 41 | F40: 99 | I40: A | J40: =A40+14 -> 46261
...

Sheet Planilha6
C4: 1 | F4: =RIGHT(N4,3) -> 001 | N4: EPR-001
C5: 2 | F5: =RIGHT(N5,3) -> 002 | N5: EPR-002
C6: 3 | F6: =RIGHT(N6,3) -> 003 | N6: EPR-003
C7: 4 | F7: =RIGHT(N7,3) -> 004 | N7: EPR-004
C8: 5 | F8: =RIGHT(N8,3) -> 005 | N8: EPR-005
C9: 6 | F9: =RIGHT(N9,3) -> 006 | N9: EPR-006
C10: 7 | F10: =RIGHT(N10,3) -> 007 | N10: EPR-007
C11: 8 | F11: =RIGHT(N11,3) -> 008 | N11: EPR-008
C12: 9 | F12: =RIGHT(N12,3) -> 009 | N12: EPR-009
C13: 10 | F13: =RIGHT(N13,3) -> 010 | N13: EPR-010
C14: 11 | F14: =RIGHT(N14,3) -> 011 | N14: EPR-011
C15: 12 | F15: =RIGHT(N15,3) -> 012 | N15: EPR-012
... C108: 197 | F108: =RIGHT(N108,3) -> 197 | N108: EPR-197

Sheet Programação Estaca
A1: Estaca | B1: Data Programada
A2: 1
A3: 2
A4: 3
A5: 4
A6: 5
A7: 6
A8: 7
A9: 8
A10: 9
A11: 10
A12: 11
A13: 12
... A225: 224

Sheet Planilha1
B2: preliminar e terraplenagem | C2: 20 | D2: preliminar e terraplenagem
B3: contrapiso | C3: 30 | D3: fundação
B4: alvenaria | C4: 15 | D4: alvenaria
B5: cobertura | C5: 35 | D5: cobertura
B6: acabamentos | C6: =SUM(C2:C5) -> 100 | D6: acabamentos
B9: ATIVIDADES PRINCIPAIS | F9: REAL | G9: CORRETO
B10: FUNDAÇÃO | C10: DRENAGEM | D10: BASE EQUIPAMENTOS | F10: TANCAGEM
B11: PROJETO | C11: PROJETO | D11: PROJETO | F11: TERRAPLENAGEM
B12: ESTAQUEAMENTO | C12: ESCAVAÇÃO | D12: PREPARO | F12: ARRUAMENTO
B13: ARRASAMENTO | C13: CAIXAS | D13: FUNDAÇÃO | F13: BASE TANQUES
B14: BLOCO | C14: TUBOS | D14: FORMA / ARMADURA | F14: BASE PIPERACK
B15: PILAR | C15: REATERRO | D15: CHUMBADORES/INSERTS | F15: DRENAGEM
B16: VIGAS LATERAIS | D16: CONCRETAGEM | F16: CONCRETAGEM PISO
B17: VIGAS DE EIXO | D17: CURA | F17: DIQUE
D18: DESFORMA
D19: GROUT
D20: CQ

Sheet Planilha2
A2: HIDW | E2: HCC
A3: Atividades preliminares
A4: Movimentação de terra
A5: Canteiro avançado / infra-estrutura
A6: Terraplenagem
A7: escavação
A8: aterro
A9: compactação
A10: Estaqueamento
A11: cravação
A12: concretagem
A13: armadura
A14: Cura
... A29: posicionamento do pilar

Sheet Planilha3
A1: QUANTIDADE ESTACAS
B2: estacas | C2: produção | D2: fator
A3: 5700-170 | B3: 24 | C3: 6 | F3: sequencia estacas
F4: Outubro a Dezembro
E5: Área | F5: 110 | G5: 240
F6: 130 | G6: 210
F7: 150 | G7: 230
F8: 170 | G8: 200
F9: 180 | G9: 190
F11: Drenagem | G11: canaletas e caixas
F12: tubos

Sheet Planilha4
A1: EPC
A2: EPC-03 | B2: U-5700
A3: EPC-03
A4: EPC-03 | B4: SE-2600
A5: EPC-03
A6: EPC-03 | B6: U-6310
A7: EPC-03
A8: EPC-03 | B8: U-6312
A9: EPC-03
A10: EPC-03 | B10: SE-6321
A11: EPC-03
A12: EPC-03 | B12: U-6411
A14: EPC-04 | B14: U-2400
A15: EPC-04
A16: EPC-04 | B16: SE-2400

Sheet Dados Dashboard
A1: DATA | B1: DIA SEMANA | C1: DIAS A PARTIR A.S. | D1: SEMANA PROGRAMAÇÃO | E1: SEM | F1: Equip 1 | G1: EIXO EQUIP 1 | H1: Equip 2 | I1: EIXO EQUIP 2 | J1: PIT | K1: PCE | L1: ESCAVAÇÃO | M1: BLOCO | N1: OBSERVAÇÃO | O1: m³ Concreto | P1: Registros Operacionais | Q1: Estacas Realizadas | R1: Observação Registrada | S1: Estaca Equip 1 | T1: Estaca Equip 2 | U1: PIT Programado | V1: PIT Vencido | W1: m³ Concreto (num) | X1: Ordem Ocorrência | Y1: Registro Duplicado | Z1: Dia com Produção | AA1: Data com Produção | AB1: PCE Registrado | AC1: Escavação Registrada | AD1: Bloco Registrado | AE1: Semana com Produção
A2: =IF(ISNUMBER('Timeline Estacas'!A2),'Timeline Estacas'!A2,"") -> 46227 | B2: =IF($A2="","",$A2) -> 46227 | C2: =IF(ISNUMBER('Timeline Estacas'!C2),'Timeline Estacas'!C2,"") -> 266 | D2: =IF(ISNUMBER('Timeline Estacas'!D2),'Timeline Estacas'!D2,"") -> 39 | E2: =IF($D2="","","S-"&TEXT($D2,"00")) -> S-39 | F2: =IF(ISNUMBER('Timeline Estacas'!F2),'Timeline Estacas'!F2,"") | G2: =IF($F2="","",IF('Timeline Estacas'!G2<>"",'Timeline Estacas'!G2,'Timeline Estacas'!I2)) | H2: =IF(ISNUMBER('Timeline Estacas'!H2),'Timeline Estacas'!H2,"") | I2: =IF($H2="","",'Timeline Estacas'!I2) | J2: =IF(ISNUMBER('Timeline Estacas'!J2),'Timeline Estacas'!J2,"") | K2: =IF('Timeline Estacas'!K2="","",'Timeline Estacas'!K2) | L2: =IF('Timeline Estacas'!L2="","",'Timeline Estacas'!L2) | M2: =IF('Timeline Estacas'!M2="","",'Timeline Estacas'!M2) | N2: =IF('Timeline Estacas'!N2="","",'Timeline Estacas'!N2) | O2: =IF(ISNUMBER('Timeline Estacas'!O2),'Timeline Estacas'!O2,"") | P2: =IF($Q2>0,1,0) -> 0 | Q2: =IF($F2="",0,1)+IF($H2="",0,1) -> 0 | R2: =IF($N2="",0,1) -> 0 | S2: =IF($F2="",0,1) -> 0 | T2: =IF($H2="",0,1) -> 0 | U2: =IF($J2="",0,1) -> 0 | V2: =IF($J2="",0,IF($J2<=TODAY(),1,0)) -> 0 | W2: =IF($O2="",0,$O2) -> 0 | X2: =IF($R2=1,SUM($R$2:$R2),"") | Y2: =IF($F2="",0,IF(COUNTIF($F$2:$F2,$F2)+COUNTIF($H$2:$H2,$F2)>1,1,0))+IF($H2="",0,IF(COUNTIF($F$2:$F2,$H2)+COUNTIF($H$2:$H2,$H2)>1,1,0)) -> 0 | Z2: =IF($Q2=0,0,IF(COUNTIFS($A$2:$A2,$A2,$Q$2:$Q2,">0")=1,1,0)) -> 0 | AA2: =IF($Q2>0,$A2,"") | AB2: =IF($K2="",0,1) -> 0 | AC2: =IF($L2="",0,1) -> 0 | AD2: =IF($M2="",0,1) -> 0 | AE2: =IF($Q2>0,$D2,"")
A3: =IF(ISNUMBER('Timeline Estacas'!A3),'Timeline Estacas'!A3,"") -> 46228 | B3: =IF($A3="","",$A3) -> 46228 | C3: =IF(ISNUMBER('Timeline Estacas'!C3),'Timeline Estacas'!C3,"") -> 267 | D3: =IF(ISNUMBER('Timeline Estacas'!D3),'Timeline Estacas'!D3,"") -> 39 | E3: =IF($D3="","","S-"&TEXT($D3,"00")) -> S-39 | F3: =IF(ISNUMBER('Timeline Estacas'!F3),'Timeline Estacas'!F3,"") | G3: =IF($F3="","",IF('Timeline Estacas'!G3<>"",'Timeline Estacas'!G3,'Timeline Estacas'!I3)) | H3: =IF(ISNUMBER('Timeline Estacas'!H3),'Timeline Estacas'!H3,"") | I3: =IF($H3="","",'Timeline Estacas'!I3) | J3: =IF(ISNUMBER('Timeline Estacas'!J3),'Timeline Estacas'!J3,"") | K3: =IF('Timeline Estacas'!K3="","",'Timeline Estacas'!K3) | L3: =IF('Timeline Estacas'!L3="","",'Timeline Estacas'!L3) | M3: =IF('Timeline Estacas'!M3="","",'Timeline Estacas'!M3) | N3: =IF('Timeline Estacas'!N3="","",'Timeline Estacas'!N3) | O3: =IF(ISNUMBER('Timeline Estacas'!O3),'Timeline Estacas'!O3,"") | P3: =IF($Q3>0,1,0) -> 0 | Q3: =IF($F3="",0,1)+IF($H3="",0,1) -> 0 | R3: =IF($N3="",0,1) -> 0 | S3: =IF($F3="",0,1) -> 0 | T3: =IF($H3="",0,1) -> 0 | U3: =IF($J3="",0,1) -> 0 | V3: =IF($J3="",0,IF($J3<=TODAY(),1,0)) -> 0 | W3: =IF($O3="",0,$O3) -> 0 | X3: =IF($R3=1,SUM($R$2:$R3),"") | Y3: =IF($F3="",0,IF(COUNTIF($F$2:$F3,$F3)+COUNTIF($H$2:$H3,$F3)>1,1,0))+IF($H3="",0,IF(COUNTIF($F$2:$F3,$H3)+COUNTIF($H$2:$H3,$H3)>1,1,0)) -> 0 | Z3: =IF($Q3=0,0,IF(COUNTIFS($A$2:$A3,$A3,$Q$2:$Q3,">0")=1,1,0)) -> 0 | AA3: =IF($Q3>0,$A3,"") | AB3: =IF($K3="",0,1) -> 0 | AC3: =IF($L3="",0,1) -> 0 | AD3: =IF($M3="",0,1) -> 0 | AE3: =IF($Q3>0,$D3,"")
A4: =IF(ISNUMBER('Timeline Estacas'!A4),'Timeline Estacas'!A4,"") -> 46229 | B4: =IF($A4="","",$A4) -> 46229 | C4: =IF(ISNUMBER('Timeline Estacas'!C4),'Timeline Estacas'!C4,"") -> 268 | D4: =IF(ISNUMBER('Timeline Estacas'!D4),'Timeline Estacas'!D4,"") -> 39 | E4: =IF($D4="","","S-"&TEXT($D4,"00")) -> S-39 | F4: =IF(ISNUMBER('Timeline Estacas'!F4),'Timeline Estacas'!F4,"") | G4: =IF($F4="","",IF('Timeline Estacas'!G4<>"",'Timeline Estacas'!G4,'Timeline Estacas'!I4)) | H4: =IF(ISNUMBER('Timeline Estacas'!H4),'Timeline Estacas'!H4,"") | I4: =IF($H4="","",'Timeline Estacas'!I4) | J4: =IF(ISNUMBER('Timeline Estacas'!J4),'Timeline Estacas'!J4,"") | K4: =IF('Timeline Estacas'!K4="","",'Timeline Estacas'!K4) | L4: =IF('Timeline Estacas'!L4="","",'Timeline Estacas'!L4) | M4: =IF('Timeline Estacas'!M4="","",'Timeline Estacas'!M4) | N4: =IF('Timeline Estacas'!N4="","",'Timeline Estacas'!N4) | O4: =IF(ISNUMBER('Timeline Estacas'!O4),'Timeline Estacas'!O4,"") | P4: =IF($Q4>0,1,0) -> 0 | Q4: =IF($F4="",0,1)+IF($H4="",0,1) -> 0 | R4: =IF($N4="",0,1) -> 0 | S4: =IF($F4="",0,1) -> 0 | T4: =IF($H4="",0,1) -> 0 | U4: =IF($J4="",0,1) -> 0 | V4: =IF($J4="",0,IF($J4<=TODAY(),1,0)) -> 0 | W4: =IF($O4="",0,$O4) -> 0 | X4: =IF($R4=1,SUM($R$2:$R4),"") | Y4: =IF($F4="",0,IF(COUNTIF($F$2:$F4,$F4)+COUNTIF($H$2:$H4,$F4)>1,1,0))+IF($H4="",0,IF(COUNTIF($F$2:$F4,$H4)+COUNTIF($H$2:$H4,$H4)>1,1,0)) -> 0 | Z4: =IF($Q4=0,0,IF(COUNTIFS($A$2:$A4,$A4,$Q$2:$Q4,">0")=1,1,0)) -> 0 | AA4: =IF($Q4>0,$A4,"") | AB4: =IF($K4="",0,1) -> 0 | AC4: =IF($L4="",0,1) -> 0 | AD4: =IF($M4="",0,1) -> 0 | AE4: =IF($Q4>0,$D4,"")
A5: =IF(ISNUMBER('Timeline Estacas'!A5),'Timeline Estacas'!A5,"") -> 46230 | B5: =IF($A5="","",$A5) -> 46230 | C5: =IF(ISNUMBER('Timeline Estacas'!C5),'Timeline Estacas'!C5,"") -> 269 | D5: =IF(ISNUMBER('Timeline Estacas'!D5),'Timeline Estacas'!D5,"") -> 39 | E5: =IF($D5="","","S-"&TEXT($D5,"00")) -> S-39 | F5: =IF(ISNUMBER('Timeline Estacas'!F5),'Timeline Estacas'!F5,"") | G5: =IF($F5="","",IF('Timeline Estacas'!G5<>"",'Timeline Estacas'!G5,'Timeline Estacas'!I5)) | H5: =IF(ISNUMBER('Timeline Estacas'!H5),'Timeline Estacas'!H5,"") | I5: =IF($H5="","",'Timeline Estacas'!I5) | J5: =IF(ISNUMBER('Timeline Estacas'!J5),'Timeline Estacas'!J5,"") | K5: =IF('Timeline Estacas'!K5="","",'Timeline Estacas'!K5) | L5: =IF('Timeline Estacas'!L5="","",'Timeline Estacas'!L5) | M5: =IF('Timeline Estacas'!M5="","",'Timeline Estacas'!M5) | N5: =IF('Timeline Estacas'!N5="","",'Timeline Estacas'!N5) | O5: =IF(ISNUMBER('Timeline Estacas'!O5),'Timeline Estacas'!O5,"") | P5: =IF($Q5>0,1,0) -> 0 | Q5: =IF($F5="",0,1)+IF($H5="",0,1) -> 0 | R5: =IF($N5="",0,1) -> 0 | S5: =IF($F5="",0,1) -> 0 | T5: =IF($H5="",0,1) -> 0 | U5: =IF($J5="",0,1) -> 0 | V5: =IF($J5="",0,IF($J5<=TODAY(),1,0)) -> 0 | W5: =IF($O5="",0,$O5) -> 0 | X5: =IF($R5=1,SUM($R$2:$R5),"") | Y5: =IF($F5="",0,IF(COUNTIF($F$2:$F5,$F5)+COUNTIF($H$2:$H5,$F5)>1,1,0))+IF($H5="",0,IF(COUNTIF($F$2:$F5,$H5)+COUNTIF($H$2:$H5,$H5)>1,1,0)) -> 0 | Z5: =IF($Q5=0,0,IF(COUNTIFS($A$2:$A5,$A5,$Q$2:$Q5,">0")=1,1,0)) -> 0 | AA5: =IF($Q5>0,$A5,"") | AB5: =IF($K5="",0,1) -> 0 | AC5: =IF($L5="",0,1) -> 0 | AD5: =IF($M5="",0,1) -> 0 | AE5: =IF($Q5>0,$D5,"")
A6: =IF(ISNUMBER('Timeline Estacas'!A6),'Timeline Estacas'!A6,"") -> 46231 | B6: =IF($A6="","",$A6) -> 46231 | C6: =IF(ISNUMBER('Timeline Estacas'!C6),'Timeline Estacas'!C6,"") -> 270 | D6: =IF(ISNUMBER('Timeline Estacas'!D6),'Timeline Estacas'!D6,"") -> 39 | E6: =IF($D6="","","S-"&TEXT($D6,"00")) -> S-39 | F6: =IF(ISNUMBER('Timeline Estacas'!F6),'Timeline Estacas'!F6,"") | G6: =IF($F6="","",IF('Timeline Estacas'!G6<>"",'Timeline Estacas'!G6,'Timeline Estacas'!I6)) | H6: =IF(ISNUMBER('Timeline Estacas'!H6),'Timeline Estacas'!H6,"") | I6: =IF($H6="","",'Timeline Estacas'!I6) | J6: =IF(ISNUMBER('Timeline Estacas'!J6),'Timeline Estacas'!J6,"") | K6: =IF('Timeline Estacas'!K6="","",'Timeline Estacas'!K6) | L6: =IF('Timeline Estacas'!L6="","",'Timeline Estacas'!L6) | M6: =IF('Timeline Estacas'!M6="","",'Timeline Estacas'!M6) | N6: =IF('Timeline Estacas'!N6="","",'Timeline Estacas'!N6) | O6: =IF(ISNUMBER('Timeline Estacas'!O6),'Timeline Estacas'!O6,"") | P6: =IF($Q6>0,1,0) -> 0 | Q6: =IF($F6="",0,1)+IF($H6="",0,1) -> 0 | R6: =IF($N6="",0,1) -> 0 | S6: =IF($F6="",0,1) -> 0 | T6: =IF($H6="",0,1) -> 0 | U6: =IF($J6="",0,1) -> 0 | V6: =IF($J6="",0,IF($J6<=TODAY(),1,0)) -> 0 | W6: =IF($O6="",0,$O6) -> 0 | X6: =IF($R6=1,SUM($R$2:$R6),"") | Y6: =IF($F6="",0,IF(COUNTIF($F$2:$F6,$F6)+COUNTIF($H$2:$H6,$F6)>1,1,0))+IF($H6="",0,IF(COUNTIF($F$2:$F6,$H6)+COUNTIF($H$2:$H6,$H6)>1,1,0)) -> 0 | Z6: =IF($Q6=0,0,IF(COUNTIFS($A$2:$A6,$A6,$Q$2:$Q6,">0")=1,1,0)) -> 0 | AA6: =IF($Q6>0,$A6,"") | AB6: =IF($K6="",0,1) -> 0 | AC6: =IF($L6="",0,1) -> 0 | AD6: =IF($M6="",0,1) -> 0 | AE6: =IF($Q6>0,$D6,"")
A7: =IF(ISNUMBER('Timeline Estacas'!A7),'Timeline Estacas'!A7,"") -> 46232 | B7: =IF($A7="","",$A7) -> 46232 | C7: =IF(ISNUMBER('Timeline Estacas'!C7),'Timeline Estacas'!C7,"") -> 271 | D7: =IF(ISNUMBER('Timeline Estacas'!D7),'Timeline Estacas'!D7,"") -> 39 | E7: =IF($D7="","","S-"&TEXT($D7,"00")) -> S-39 | F7: =IF(ISNUMBER('Timeline Estacas'!F7),'Timeline Estacas'!F7,"") | G7: =IF($F7="","",IF('Timeline Estacas'!G7<>"",'Timeline Estacas'!G7,'Timeline Estacas'!I7)) | H7: =IF(ISNUMBER('Timeline Estacas'!H7),'Timeline Estacas'!H7,"") | I7: =IF($H7="","",'Timeline Estacas'!I7) | J7: =IF(ISNUMBER('Timeline Estacas'!J7),'Timeline Estacas'!J7,"") | K7: =IF('Timeline Estacas'!K7="","",'Timeline Estacas'!K7) | L7: =IF('Timeline Estacas'!L7="","",'Timeline Estacas'!L7) | M7: =IF('Timeline Estacas'!M7="","",'Timeline Estacas'!M7) | N7: =IF('Timeline Estacas'!N7="","",'Timeline Estacas'!N7) -> Teste inicial do equipamento | O7: =IF(ISNUMBER('Timeline Estacas'!O7),'Timeline Estacas'!O7,"") | P7: =IF($Q7>0,1,0) -> 0 | Q7: =IF($F7="",0,1)+IF($H7="",0,1) -> 0 | R7: =IF($N7="",0,1) -> 1 | S7: =IF($F7="",0,1) -> 0 | T7: =IF($H7="",0,1) -> 0 | U7: =IF($J7="",0,1) -> 0 | V7: =IF($J7="",0,IF($J7<=TODAY(),1,0)) -> 0 | W7: =IF($O7="",0,$O7) -> 0 | X7: =IF($R7=1,SUM($R$2:$R7),"") -> 1 | Y7: =IF($F7="",0,IF(COUNTIF($F$2:$F7,$F7)+COUNTIF($H$2:$H7,$F7)>1,1,0))+IF($H7="",0,IF(COUNTIF($F$2:$F7,$H7)+COUNTIF($H$2:$H7,$H7)>1,1,0)) -> 0 | Z7: =IF($Q7=0,0,IF(COUNTIFS($A$2:$A7,$A7,$Q$2:$Q7,">0")=1,1,0)) -> 0 | AA7: =IF($Q7>0,$A7,"") | AB7: =IF($K7="",0,1) -> 0 | AC7: =IF($L7="",0,1) -> 0 | AD7: =IF($M7="",0,1) -> 0 | AE7: =IF($Q7>0,$D7,"")
A8: =IF(ISNUMBER('Timeline Estacas'!A8),'Timeline Estacas'!A8,"") -> 46233 | B8: =IF($A8="","",$A8) -> 46233 | C8: =IF(ISNUMBER('Timeline Estacas'!C8),'Timeline Estacas'!C8,"") -> 272 | D8: =IF(ISNUMBER('Timeline Estacas'!D8),'Timeline Estacas'!D8,"") -> 39 | E8: =IF($D8="","","S-"&TEXT($D8,"00")) -> S-39 | F8: =IF(ISNUMBER('Timeline Estacas'!F8),'Timeline Estacas'!F8,"") -> 70 | G8: =IF($F8="","",IF('Timeline Estacas'!G8<>"",'Timeline Estacas'!G8,'Timeline Estacas'!I8)) -> A | H8: =IF(ISNUMBER('Timeline Estacas'!H8),'Timeline Estacas'!H8,"") | I8: =IF($H8="","",'Timeline Estacas'!I8) | J8: =IF(ISNUMBER('Timeline Estacas'!J8),'Timeline Estacas'!J8,"") -> 46247 | K8: =IF('Timeline Estacas'!K8="","",'Timeline Estacas'!K8) | L8: =IF('Timeline Estacas'!L8="","",'Timeline Estacas'!L8) | M8: =IF('Timeline Estacas'!M8="","",'Timeline Estacas'!M8) | N8: =IF('Timeline Estacas'!N8="","",'Timeline Estacas'!N8) | O8: =IF(ISNUMBER('Timeline Estacas'!O8),'Timeline Estacas'!O8,"") | P8: =IF($Q8>0,1,0) -> 1 | Q8: =IF($F8="",0,1)+IF($H8="",0,1) -> 1 | R8: =IF($N8="",0,1) -> 0 | S8: =IF($F8="",0,1) -> 1 | T8: =IF($H8="",0,1) -> 0 | U8: =IF($J8="",0,1) -> 1 | V8: =IF($J8="",0,IF($J8<=TODAY(),1,0)) -> 1 | W8: =IF($O8="",0,$O8) -> 0 | X8: =IF($R8=1,SUM($R$2:$R8),"") | Y8: =IF($F8="",0,IF(COUNTIF($F$2:$F8,$F8)+COUNTIF($H$2:$H8,$F8)>1,1,0))+IF($H8="",0,IF(COUNTIF($F$2:$F8,$H8)+COUNTIF($H$2:$H8,$H8)>1,1,0)) -> 0 | Z8: =IF($Q8=0,0,IF(COUNTIFS($A$2:$A8,$A8,$Q$2:$Q8,">0")=1,1,0)) -> 1 | AA8: =IF($Q8>0,$A8,"") -> 46233 | AB8: =IF($K8="",0,1) -> 0 | AC8: =IF($L8="",0,1) -> 0 | AD8: =IF($M8="",0,1) -> 0 | AE8: =IF($Q8>0,$D8,"") -> 39
A9: =IF(ISNUMBER('Timeline Estacas'!A9),'Timeline Estacas'!A9,"") -> 46233 | B9: =IF($A9="","",$A9) -> 46233 | C9: =IF(ISNUMBER('Timeline Estacas'!C9),'Timeline Estacas'!C9,"") -> 272 | D9: =IF(ISNUMBER('Timeline Estacas'!D9),'Timeline Estacas'!D9,"") -> 39 | E9: =IF($D9="","","S-"&TEXT($D9,"00")) -> S-39 | F9: =IF(ISNUMBER('Timeline Estacas'!F9),'Timeline Estacas'!F9,"") -> 71 | G9: =IF($F9="","",IF('Timeline Estacas'!G9<>"",'Timeline Estacas'!G9,'Timeline Estacas'!I9)) -> A | H9: =IF(ISNUMBER('Timeline Estacas'!H9),'Timeline Estacas'!H9,"") | I9: =IF($H9="","",'Timeline Estacas'!I9) | J9: =IF(ISNUMBER('Timeline Estacas'!J9),'Timeline Estacas'!J9,"") -> 46247 | K9: =IF('Timeline Estacas'!K9="","",'Timeline Estacas'!K9) | L9: =IF('Timeline Estacas'!L9="","",'Timeline Estacas'!L9) | M9: =IF('Timeline Estacas'!M9="","",'Timeline Estacas'!M9) | N9: =IF('Timeline Estacas'!N9="","",'Timeline Estacas'!N9) | O9: =IF(ISNUMBER('Timeline Estacas'!O9),'Timeline Estacas'!O9,"") | P9: =IF($Q9>0,1,0) -> 1 | Q9: =IF($F9="",0,1)+IF($H9="",0,1) -> 1 | R9: =IF($N9="",0,1) -> 0 | S9: =IF($F9="",0,1) -> 1 | T9: =IF($H9="",0,1) -> 0 | U9: =IF($J9="",0,1) -> 1 | V9: =IF($J9="",0,IF($J9<=TODAY(),1,0)) -> 1 | W9: =IF($O9="",0,$O9) -> 0 | X9: =IF($R9=1,SUM($R$2:$R9),"") | Y9: =IF($F9="",0,IF(COUNTIF($F$2:$F9,$F9)+COUNTIF($H$2:$H9,$F9)>1,1,0))+IF($H9="",0,IF(COUNTIF($F$2:$F9,$H9)+COUNTIF($H$2:$H9,$H9)>1,1,0)) -> 0 | Z9: =IF($Q9=0,0,IF(COUNTIFS($A$2:$A9,$A9,$Q$2:$Q9,">0")=1,1,0)) -> 0 | AA9: =IF($Q9>0,$A9,"") -> 46233 | AB9: =IF($K9="",0,1) -> 0 | AC9: =IF($L9="",0,1) -> 0 | AD9: =IF($M9="",0,1) -> 0 | AE9: =IF($Q9>0,$D9,"") -> 39
A10: =IF(ISNUMBER('Timeline Estacas'!A10),'Timeline Estacas'!A10,"") -> 46233 | B10: =IF($A10="","",$A10) -> 46233 | C10: =IF(ISNUMBER('Timeline Estacas'!C10),'Timeline Estacas'!C10,"") -> 272 | D10: =IF(ISNUMBER('Timeline Estacas'!D10),'Timeline Estacas'!D10,"") -> 39 | E10: =IF($D10="","","S-"&TEXT($D10,"00")) -> S-39 | F10: =IF(ISNUMBER('Timeline Estacas'!F10),'Timeline Estacas'!F10,"") -> 74 | G10: =IF($F10="","",IF('Timeline Estacas'!G10<>"",'Timeline Estacas'!G10,'Timeline Estacas'!I10)) -> A | H10: =IF(ISNUMBER('Timeline Estacas'!H10),'Timeline Estacas'!H10,"") | I10: =IF($H10="","",'Timeline Estacas'!I10) | J10: =IF(ISNUMBER('Timeline Estacas'!J10),'Timeline Estacas'!J10,"") -> 46247 | K10: =IF('Timeline Estacas'!K10="","",'Timeline Estacas'!K10) | L10: =IF('Timeline Estacas'!L10="","",'Timeline Estacas'!L10) | M10: =IF('Timeline Estacas'!M10="","",'Timeline Estacas'!M10) | N10: =IF('Timeline Estacas'!N10="","",'Timeline Estacas'!N10) | O10: =IF(ISNUMBER('Timeline Estacas'!O10),'Timeline Estacas'!O10,"") | P10: =IF($Q10>0,1,0) -> 1 | Q10: =IF($F10="",0,1)+IF($H10="",0,1) -> 1 | R10: =IF($N10="",0,1) -> 0 | S10: =IF($F10="",0,1) -> 1 | T10: =IF($H10="",0,1) -> 0 | U10: =IF($J10="",0,1) -> 1 | V10: =IF($J10="",0,IF($J10<=TODAY(),1,0)) -> 1 | W10: =IF($O10="",0,$O10) -> 0 | X10: =IF($R10=1,SUM($R$2:$R10),"") | Y10: =IF($F10="",0,IF(COUNTIF($F$2:$F10,$F10)+COUNTIF($H$2:$H10,$F10)>1,1,0))+IF($H10="",0,IF(COUNTIF($F$2:$F10,$H10)+COUNTIF($H$2:$H10,$H10)>1,1,0)) -> 0 | Z10: =IF($Q10=0,0,IF(COUNTIFS($A$2:$A10,$A10,$Q$2:$Q10,">0")=1,1,0)) -> 0 | AA10: =IF($Q10>0,$A10,"") -> 46233 | AB10: =IF($K10="",0,1) -> 0 | AC10: =IF($L10="",0,1) -> 0 | AD10: =IF($M10="",0,1) -> 0 | AE10: =IF($Q10>0,$D10,"") -> 39
A11: =IF(ISNUMBER('Timeline Estacas'!A11),'Timeline Estacas'!A11,"") -> 46234 | B11: =IF($A11="","",$A11) -> 46234 | C11: =IF(ISNUMBER('Timeline Estacas'!C11),'Timeline Estacas'!C11,"") -> 273 | D11: =IF(ISNUMBER('Timeline Estacas'!D11),'Timeline Estacas'!D11,"") -> 40 | E11: =IF($D11="","","S-"&TEXT($D11,"00")) -> S-40 | F11: =IF(ISNUMBER('Timeline Estacas'!F11),'Timeline Estacas'!F11,"") | G11: =IF($F11="","",IF('Timeline Estacas'!G11<>"",'Timeline Estacas'!G11,'Timeline Estacas'!I11)) | H11: =IF(ISNUMBER('Timeline Estacas'!H11),'Timeline Estacas'!H11,"") | I11: =IF($H11="","",'Timeline Estacas'!I11) | J11: =IF(ISNUMBER('Timeline Estacas'!J11),'Timeline Estacas'!J11,"") | K11: =IF('Timeline Estacas'!K11="","",'Timeline Estacas'!K11) | L11: =IF('Timeline Estacas'!L11="","",'Timeline Estacas'!L11) | M11: =IF('Timeline Estacas'!M11="","",'Timeline Estacas'!M11) | N11: =IF('Timeline Estacas'!N11="","",'Timeline Estacas'!N11) -> Bomba entupida | O11: =IF(ISNUMBER('Timeline Estacas'!O11),'Timeline Estacas'!O11,"") | P11: =IF($Q11>0,1,0) -> 0 | Q11: =IF($F11="",0,1)+IF($H11="",0,1) -> 0 | R11: =IF($N11="",0,1) -> 1 | S11: =IF($F11="",0,1) -> 0 | T11: =IF($H11="",0,1) -> 0 | U11: =IF($J11="",0,1) -> 0 | V11: =IF($J11="",0,IF($J11<=TODAY(),1,0)) -> 0 | W11: =IF($O11="",0,$O11) -> 0 | X11: =IF($R11=1,SUM($R$2:$R11),"") -> 2 | Y11: =IF($F11="",0,IF(COUNTIF($F$2:$F11,$F11)+COUNTIF($H$2:$H11,$F11)>1,1,0))+IF($H11="",0,IF(COUNTIF($F$2:$F11,$H11)+COUNTIF($H$2:$H11,$H11)>1,1,0)) -> 0 | Z11: =IF($Q11=0,0,IF(COUNTIFS($A$2:$A11,$A11,$Q$2:$Q11,">0")=1,1,0)) -> 0 | AA11: =IF($Q11>0,$A11,"") | AB11: =IF($K11="",0,1) -> 0 | AC11: =IF($L11="",0,1) -> 0 | AD11: =IF($M11="",0,1) -> 0 | AE11: =IF($Q11>0,$D11,"")
A12: =IF(ISNUMBER('Timeline Estacas'!A12),'Timeline Estacas'!A12,"") -> 46235 | B12: =IF($A12="","",$A12) -> 46235 | C12: =IF(ISNUMBER('Timeline Estacas'!C12),'Timeline Estacas'!C12,"") -> 274 | D12: =IF(ISNUMBER('Timeline Estacas'!D12),'Timeline Estacas'!D12,"") -> 40 | E12: =IF($D12="","","S-"&TEXT($D12,"00")) -> S-40 | F12: =IF(ISNUMBER('Timeline Estacas'!F12),'Timeline Estacas'!F12,"") | G12: =IF($F12="","",IF('Timeline Estacas'!G12<>"",'Timeline Estacas'!G12,'Timeline Estacas'!I12)) | H12: =IF(ISNUMBER('Timeline Estacas'!H12),'Timeline Estacas'!H12,"") | I12: =IF($H12="","",'Timeline Estacas'!I12) | J12: =IF(ISNUMBER('Timeline Estacas'!J12),'Timeline Estacas'!J12,"") | K12: =IF('Timeline Estacas'!K12="","",'Timeline Estacas'!K12) | L12: =IF('Timeline Estacas'!L12="","",'Timeline Estacas'!L12) | M12: =IF('Timeline Estacas'!M12="","",'Timeline Estacas'!M12) | N12: =IF('Timeline Estacas'!N12="","",'Timeline Estacas'!N12) | O12: =IF(ISNUMBER('Timeline Estacas'!O12),'Timeline Estacas'!O12,"") | P12: =IF($Q12>0,1,0) -> 0 | Q12: =IF($F12="",0,1)+IF($H12="",0,1) -> 0 | R12: =IF($N12="",0,1) -> 0 | S12: =IF($F12="",0,1) -> 0 | T12: =IF($H12="",0,1) -> 0 | U12: =IF($J12="",0,1) -> 0 | V12: =IF($J12="",0,IF($J12<=TODAY(),1,0)) -> 0 | W12: =IF($O12="",0,$O12) -> 0 | X12: =IF($R12=1,SUM($R$2:$R12),"") | Y12: =IF($F12="",0,IF(COUNTIF($F$2:$F12,$F12)+COUNTIF($H$2:$H12,$F12)>1,1,0))+IF($H12="",0,IF(COUNTIF($F$2:$F12,$H12)+COUNTIF($H$2:$H12,$H12)>1,1,0)) -> 0 | Z12: =IF($Q12=0,0,IF(COUNTIFS($A$2:$A12,$A12,$Q$2:$Q12,">0")=1,1,0)) -> 0 | AA12: =IF($Q12>0,$A12,"") | AB12: =IF($K12="",0,1) -> 0 | AC12: =IF($L12="",0,1) -> 0 | AD12: =IF($M12="",0,1) -> 0 | AE12: =IF($Q12>0,$D12,"")
A13: =IF(ISNUMBER('Timeline Estacas'!A13),'Timeline Estacas'!A13,"") -> 46236 | B13: =IF($A13="","",$A13) -> 46236 | C13: =IF(ISNUMBER('Timeline Estacas'!C13),'Timeline Estacas'!C13,"") -> 275 | D13: =IF(ISNUMBER('Timeline Estacas'!D13),'Timeline Estacas'!D13,"") -> 40 | E13: =IF($D13="","","S-"&TEXT($D13,"00")) -> S-40 | F13: =IF(ISNUMBER('Timeline Estacas'!F13),'Timeline Estacas'!F13,"") | G13: =IF($F13="","",IF('Timeline Estacas'!G13<>"",'Timeline Estacas'!G13,'Timeline Estacas'!I13)) | H13: =IF(ISNUMBER('Timeline Estacas'!H13),'Timeline Estacas'!H13,"") | I13: =IF($H13="","",'Timeline Estacas'!I13) | J13: =IF(ISNUMBER('Timeline Estacas'!J13),'Timeline Estacas'!J13,"") | K13: =IF('Timeline Estacas'!K13="","",'Timeline Estacas'!K13) | L13: =IF('Timeline Estacas'!L13="","",'Timeline Estacas'!L13) | M13: =IF('Timeline Estacas'!M13="","",'Timeline Estacas'!M13) | N13: =IF('Timeline Estacas'!N13="","",'Timeline Estacas'!N13) | O13: =IF(ISNUMBER('Timeline Estacas'!O13),'Timeline Estacas'!O13,"") | P13: =IF($Q13>0,1,0) -> 0 | Q13: =IF($F13="",0,1)+IF($H13="",0,1) -> 0 | R13: =IF($N13="",0,1) -> 0 | S13: =IF($F13="",0,1) -> 0 | T13: =IF($H13="",0,1) -> 0 | U13: =IF($J13="",0,1) -> 0 | V13: =IF($J13="",0,IF($J13<=TODAY(),1,0)) -> 0 | W13: =IF($O13="",0,$O13) -> 0 | X13: =IF($R13=1,SUM($R$2:$R13),"") | Y13: =IF($F13="",0,IF(COUNTIF($F$2:$F13,$F13)+COUNTIF($H$2:$H13,$F13)>1,1,0))+IF($H13="",0,IF(COUNTIF($F$2:$F13,$H13)+COUNTIF($H$2:$H13,$H13)>1,1,0)) -> 0 | Z13: =IF($Q13=0,0,IF(COUNTIFS($A$2:$A13,$A13,$Q$2:$Q13,">0")=1,1,0)) -> 0 | AA13: =IF($Q13>0,$A13,"") | AB13: =IF($K13="",0,1) -> 0 | AC13: =IF($L13="",0,1) -> 0 | AD13: =IF($M13="",0,1) -> 0 | AE13: =IF($Q13>0,$D13,"")
... A243: =IF(ISNUMBER('Timeline Estacas'!A243),'Timeline Estacas'!A243,"") -> 46387 | B243: =IF($A243="","",$A243) -> 46387 | C243: =IF(ISNUMBER('Timeline Estacas'!C243),'Timeline Estacas'!C243,"") -> 426 | D243: =IF(ISNUMBER('Timeline Estacas'!D243),'Timeline Estacas'!D243,"") -> 61 | E243: =IF($D243="","","S-"&TEXT($D243,"00")) -> S-61 | F243: =IF(ISNUMBER('Timeline Estacas'!F243),'Timeline Estacas'!F243,"") | G243: =IF($F243="","",IF('Timeline Estacas'!G243<>"",'Timeline Estacas'!G243,'Timeline Estacas'!I243)) | H243: =IF(ISNUMBER('Timeline Estacas'!H243),'Timeline Estacas'!H243,"") | I243: =IF($H243="","",'Timeline Estacas'!I243) | J243: =IF(ISNUMBER('Timeline Estacas'!J243),'Timeline Estacas'!J243,"") | K243: =IF('Timeline Estacas'!K243="","",'Timeline Estacas'!K243) | L243: =IF('Timeline Estacas'!L243="","",'Timeline Estacas'!L243) | M243: =IF('Timeline Estacas'!M243="","",'Timeline Estacas'!M243) | N243: =IF('Timeline Estacas'!N243="","",'Timeline Estacas'!N243) | O243: =IF(ISNUMBER('Timeline Estacas'!O243),'Timeline Estacas'!O243,"") | P243: =IF($Q243>0,1,0) -> 0 | Q243: =IF($F243="",0,1)+IF($H243="",0,1) -> 0 | R243: =IF($N243="",0,1) -> 0 | S243: =IF($F243="",0,1) -> 0 | T243: =IF($H243="",0,1) -> 0 | U243: =IF($J243="",0,1) -> 0 | V243: =IF($J243="",0,IF($J243<=TODAY(),1,0)) -> 0 | W243: =IF($O243="",0,$O243) -> 0 | X243: =IF($R243=1,SUM($R$2:$R243),"") | Y243: =IF($F243="",0,IF(COUNTIF($F$2:$F243,$F243)+COUNTIF($H$2:$H243,$F243)>1,1,0))+IF($H243="",0,IF(COUNTIF($F$2:$F243,$H243)+COUNTIF($H$2:$H243,$H243)>1,1,0)) -> 0 | Z243: =IF($Q243=0,0,IF(COUNTIFS($A$2:$A243,$A243,$Q$2:$Q243,">0")=1,1,0)) -> 0 | AA243: =IF($Q243>0,$A243,"") | AB243: =IF($K243="",0,1) -> 0 | AC243: =IF($L243="",0,1) -> 0 | AD243: =IF($M243="",0,1) -> 0 | AE243: =IF($Q243>0,$D243,"")

Sheet Listas
A1: Filtro de semana | C1: Indicador
A2: TODAS | C2: Equip 1
A3: S-39 | C3: Equip 2
A4: S-40 | C4: PIT
A5: S-41 | C5: PCE
A6: S-42 | C6: Escavação
A7: S-43 | C7: Bloco
A8: S-44 | C8: Observações
A9: S-45
A10: S-46
A11: S-47
A12: S-48
A13: S-49
A14: S-50
A15: S-51
A16: S-52
A17: S-53
A18: S-54
A19: S-55
A20: S-56
... A25: S-61

Sheet Leia-me
B2: GUIA RÁPIDO | TIMELINE DE ESTACAS
B4: OBJETIVO
B5: Acompanhar o avanço físico do estaqueamento: quanto já foi executado, em que ritmo, com qual equipamento, quais ensaios PIT estão programados/vencidos e quais ocorrências pararam a frente.
B9: ONDE LANÇAR
B10: Lance SOMENTE na aba "Timeline Estacas", uma linha por estaca executada: DATA, número da estaca em "Equip 1" ou "Equip 2", o EIXO e a OBSERVAÇÃO do dia. O PIT é calculado automaticamente (data de execução + 14 dias).
B14: ABAS DO ARQUIVO
B15: Dashboard = leitura gerencial (não editar, exceto os filtros). Timeline Estacas = lançamento diário. Dados Dashboard = camada de cálculo, 100% em fórmulas espelhando a Timeline — não digitar nada. Programação Estaca = escopo contratual (224 estacas). Listas = opções do filtro de semana.
B19: COMO USAR O DASHBOARD
B20: O bloco "AVANÇO FÍSICO" mostra o acumulado de todo o escopo e NÃO responde aos filtros. O bloco "DESEMPENHO NO RECORTE" responde aos filtros de semana e de datas. Para voltar à visão completa, escolha "TODAS" em Semana selecionada.
B24: INDICADORES
B25: Estacas Realizadas = estacas efetivamente executadas (Equip 1 + Equip 2). Estacas Programadas = escopo total. Saldo = programadas − realizadas. Ritmo Médio = realizadas ÷ dias com produção (produtividade quando a frente opera). Ritmo Efetivo = realizadas ÷ dias úteis decorridos, já com as paradas embutidas — é ele que alimenta a Previsão de Término (estimativa). PIT Vencido = data programada do ensaio já passou da data de referência.
B29: CONSISTÊNCIA
... B35: Ao abrir, o Excel recalcula tudo sozinho. A grade de datas da Timeline vai de 24/07/2026 a 31/12/2026 (linhas 2 a 243). Se novas linhas forem acrescentadas além da 243, estenda também as fórmulas da aba "Dados Dashboard" até a mesma linha.
